<!--
  UR5e 机械臂本体 MJCF
  来源: Universal Robots UR5e + Robotiq 85 + RealSense D435
  
  包含 6 个旋转关节:
    ur_shoulder_pan_joint, ur_shoulder_lift_joint, ur_elbow_joint,
    ur_wrist_1_joint, ur_wrist_2_joint, ur_wrist_3_joint
  
  actuator 使用 position 模式,支持关节位置增量控制
-->
<mujoco model="ur5e_arm">
  <compiler angle="radian" meshdir="meshes" autolimits="true" balanceinertia="true"/>
  <option gravity="0 0 -9.81" integrator="implicitfast" impratio="10"/>

  <visual>
    <global offwidth="640" offheight="480"/>
    <quality shadowsize="4096"/>
  </visual>

  <default>
    <default class="robot">
      <default class="visual">
        <geom contype="0" conaffinity="0" group="2"/>
      </default>
      <default class="collision">
        <geom contype="1" conaffinity="1" group="3" condim="4"/>
      </default>
    </default>
  </default>

  <asset>
    <!-- Base -->
    <mesh name="MESH_base_bd1b2dd6" file="base_bd1b2dd6.stl"/>
    <mesh name="MESH_base_b81001a2_0" file="base_b81001a2_0.obj"/>
    <mesh name="MESH_base_b81001a2_1" file="base_b81001a2_1.obj"/>
    <!-- Shoulder -->
    <mesh name="MESH_shoulder_661339ad" file="shoulder_661339ad.stl"/>
    <mesh name="MESH_shoulder_0fe2d913_0" file="shoulder_0fe2d913_0.obj"/>
    <mesh name="MESH_shoulder_0fe2d913_1" file="shoulder_0fe2d913_1.obj"/>
    <mesh name="MESH_shoulder_0fe2d913_2" file="shoulder_0fe2d913_2.obj"/>
    <!-- Upper arm -->
    <mesh name="MESH_upperarm_d0455716" file="upperarm_d0455716.stl"/>
    <mesh name="MESH_upperarm_12b51e98_0" file="upperarm_12b51e98_0.obj"/>
    <mesh name="MESH_upperarm_12b51e98_1" file="upperarm_12b51e98_1.obj"/>
    <mesh name="MESH_upperarm_12b51e98_2" file="upperarm_12b51e98_2.obj"/>
    <mesh name="MESH_upperarm_12b51e98_3" file="upperarm_12b51e98_3.obj"/>
    <mesh name="MESH_upperarm_12b51e98_4" file="upperarm_12b51e98_4.obj"/>
    <mesh name="MESH_upperarm_12b51e98_5" file="upperarm_12b51e98_5.obj"/>
    <mesh name="MESH_upperarm_12b51e98_6" file="upperarm_12b51e98_6.obj"/>
    <mesh name="MESH_upperarm_12b51e98_7" file="upperarm_12b51e98_7.obj"/>
    <!-- Forearm -->
    <mesh name="MESH_forearm_98bdcf8e" file="forearm_98bdcf8e.stl"/>
    <mesh name="MESH_forearm_861ccd15_0" file="forearm_861ccd15_0.obj"/>
    <mesh name="MESH_forearm_861ccd15_1" file="forearm_861ccd15_1.obj"/>
    <mesh name="MESH_forearm_861ccd15_2" file="forearm_861ccd15_2.obj"/>
    <mesh name="MESH_forearm_861ccd15_3" file="forearm_861ccd15_3.obj"/>
    <mesh name="MESH_forearm_861ccd15_4" file="forearm_861ccd15_4.obj"/>
    <mesh name="MESH_forearm_861ccd15_5" file="forearm_861ccd15_5.obj"/>
    <mesh name="MESH_forearm_861ccd15_6" file="forearm_861ccd15_6.obj"/>
    <!-- Wrist 1 -->
    <mesh name="MESH_wrist1_2df87b9f" file="wrist1_2df87b9f.stl"/>
    <mesh name="MESH_wrist1_1e3ee180_0" file="wrist1_1e3ee180_0.obj"/>
    <mesh name="MESH_wrist1_1e3ee180_1" file="wrist1_1e3ee180_1.obj"/>
    <mesh name="MESH_wrist1_1e3ee180_2" file="wrist1_1e3ee180_2.obj"/>
    <!-- Wrist 2 -->
    <mesh name="MESH_wrist2_e6869549" file="wrist2_e6869549.stl"/>
    <mesh name="MESH_wrist2_bde41993_0" file="wrist2_bde41993_0.obj"/>
    <mesh name="MESH_wrist2_bde41993_1" file="wrist2_bde41993_1.obj"/>
    <mesh name="MESH_wrist2_bde41993_2" file="wrist2_bde41993_2.obj"/>
    <!-- Wrist 3 -->
    <mesh name="MESH_wrist3_21abe53b" file="wrist3_21abe53b.stl"/>
    <mesh name="MESH_wrist3_8e7adc5c_0" file="wrist3_8e7adc5c_0.obj"/>
  </asset>

  <worldbody>
    <body name="ur_base_link" pos="0 0 0.1" quat="1 0 0 0">
      <body name="ur_base_link_inertia" pos="0 0 0" quat="6.123233995736766e-17 0 0 1">
        <inertial mass="4.0" diaginertia="0.00443333156 0.00443333156 0.0072" pos="0 0 0" quat="1 0 0 0"/>
        <geom class="collision" name="COLLISION_ur_base_link_inertia_0" type="mesh" mesh="MESH_base_bd1b2dd6" pos="0 0 0" quat="6.123233995736766e-17 0 0 1"/>
        <geom class="visual" name="VISUAL_ur_base_link_inertia_0" type="mesh" mesh="MESH_base_b81001a2_0" rgba="0.278 0.278 0.278 1" pos="0 0 0" quat="6.123233995736766e-17 0 0 1"/>
        <geom class="visual" name="VISUAL_ur_base_link_inertia_1" type="mesh" mesh="MESH_base_b81001a2_1" rgba="0.031 0.031 0.031 1" pos="0 0 0" quat="6.123233995736766e-17 0 0 1"/>

        <body name="ur_shoulder_link" pos="0 0 0.1625" quat="1 0 0 0">
          <inertial mass="3.761" diaginertia="0.006024775831167757 0.0070003048838239885 0.007030789285008251" pos="0.0 -0.00193 -0.02561" quat="0.20206705998679322 0.6747312134749398 0.365097644892179 -0.6087777940473136"/>
          <joint name="ur_shoulder_pan_joint" type="hinge" axis="0 0 1" range="-6.283185307179586 6.283185307179586"/>
          <geom class="collision" name="COLLISION_ur_shoulder_link_0" type="mesh" mesh="MESH_shoulder_661339ad" pos="0 0 0" quat="6.123233995736766e-17 0 0 1"/>
          <geom class="visual" name="VISUAL_ur_shoulder_link_0" type="mesh" mesh="MESH_shoulder_0fe2d913_0" rgba="0.278 0.278 0.278 1" pos="0 0 0" quat="6.123233995736766e-17 0 0 1"/>
          <geom class="visual" name="VISUAL_ur_shoulder_link_1" type="mesh" mesh="MESH_shoulder_0fe2d913_1" rgba="0.031 0.031 0.031 1" pos="0 0 0" quat="6.123233995736766e-17 0 0 1"/>
          <geom class="visual" name="VISUAL_ur_shoulder_link_2" type="mesh" mesh="MESH_shoulder_0fe2d913_2" rgba="0.490 0.678 0.8 1" pos="0 0 0" quat="6.123233995736766e-17 0 0 1"/>

          <body name="ur_upper_arm_link" pos="0 0 0" quat="0.7071067811140325 0.7071067812590626 0 0">
            <inertial mass="8.058" diaginertia="0.015058840753982044 0.3324720677719464 0.3338808714740716" pos="-0.2125 0.0 0.11336" quat="0.7066521546519151 0.7075611104882223 5.365436380901162e-05 -6.611874721869904e-05"/>
            <joint name="ur_shoulder_lift_joint" type="hinge" axis="0 0 1" range="-6.283185307179586 6.283185307179586"/>
            <geom class="collision" name="COLLISION_ur_upper_arm_link_0" type="mesh" mesh="MESH_upperarm_d0455716" pos="0 0 0.138" quat="0.5 0.5 -0.5 -0.5"/>
            <geom class="visual" name="VISUAL_ur_upper_arm_link_0" type="mesh" mesh="MESH_upperarm_12b51e98_0" rgba="0.490 0.678 0.8 1" pos="0 0 0.138" quat="0.5 0.5 -0.5 -0.5"/>
            <geom class="visual" name="VISUAL_ur_upper_arm_link_1" type="mesh" mesh="MESH_upperarm_12b51e98_1" rgba="0.278 0.278 0.278 1" pos="0 0 0.138" quat="0.5 0.5 -0.5 -0.5"/>
            <geom class="visual" name="VISUAL_ur_upper_arm_link_2" type="mesh" mesh="MESH_upperarm_12b51e98_2" rgba="0.031 0.031 0.031 1" pos="0 0 0.138" quat="0.5 0.5 -0.5 -0.5"/>
            <geom class="visual" name="VISUAL_ur_upper_arm_link_3" type="mesh" mesh="MESH_upperarm_12b51e98_3" rgba="0.490 0.678 0.8 1" pos="0 0 0.138" quat="0.5 0.5 -0.5 -0.5"/>
            <geom class="visual" name="VISUAL_ur_upper_arm_link_4" type="mesh" mesh="MESH_upperarm_12b51e98_4" rgba="0.820 0.820 0.820 1" pos="0 0 0.138" quat="0.5 0.5 -0.5 -0.5"/>
            <geom class="visual" name="VISUAL_ur_upper_arm_link_5" type="mesh" mesh="MESH_upperarm_12b51e98_5" rgba="0.031 0.031 0.031 1" pos="0 0 0.138" quat="0.5 0.5 -0.5 -0.5"/>
            <geom class="visual" name="VISUAL_ur_upper_arm_link_6" type="mesh" mesh="MESH_upperarm_12b51e98_6" rgba="0.278 0.278 0.278 1" pos="0 0 0.138" quat="0.5 0.5 -0.5 -0.5"/>
            <geom class="visual" name="VISUAL_ur_upper_arm_link_7" type="mesh" mesh="MESH_upperarm_12b51e98_7" rgba="0.031 0.031 0.031 1" pos="0 0 0.138" quat="0.5 0.5 -0.5 -0.5"/>

            <body name="ur_forearm_link" pos="-0.425 0 0" quat="1 0 0 0">
              <inertial mass="2.846" diaginertia="0.003971028904819707 0.0785102224320644 0.07879270866311583" pos="-0.2422 0.0 0.0265" quat="0.6984488939206283 0.715600664432383 -0.006368275363090868 -0.006654074983260038"/>
              <joint name="ur_elbow_joint" type="hinge" axis="0 0 1" range="-3.141592653589793 3.141592653589793"/>
              <geom class="collision" name="COLLISION_ur_forearm_link_0" type="mesh" mesh="MESH_forearm_98bdcf8e" pos="0 0 0.007" quat="0.5 0.5 -0.5 -0.5"/>
              <geom class="visual" name="VISUAL_ur_forearm_link_0" type="mesh" mesh="MESH_forearm_861ccd15_0" rgba="0.278 0.278 0.278 1" pos="0 0 0.007" quat="0.5 0.5 -0.5 -0.5"/>
              <geom class="visual" name="VISUAL_ur_forearm_link_1" type="mesh" mesh="MESH_forearm_861ccd15_1" rgba="0.278 0.278 0.278 1" pos="0 0 0.007" quat="0.5 0.5 -0.5 -0.5"/>
              <geom class="visual" name="VISUAL_ur_forearm_link_2" type="mesh" mesh="MESH_forearm_861ccd15_2" rgba="0.031 0.031 0.031 1" pos="0 0 0.007" quat="0.5 0.5 -0.5 -0.5"/>
              <geom class="visual" name="VISUAL_ur_forearm_link_3" type="mesh" mesh="MESH_forearm_861ccd15_3" rgba="0.820 0.820 0.820 1" pos="0 0 0.007" quat="0.5 0.5 -0.5 -0.5"/>
              <geom class="visual" name="VISUAL_ur_forearm_link_4" type="mesh" mesh="MESH_forearm_861ccd15_4" rgba="0.031 0.031 0.031 1" pos="0 0 0.007" quat="0.5 0.5 -0.5 -0.5"/>
              <geom class="visual" name="VISUAL_ur_forearm_link_5" type="mesh" mesh="MESH_forearm_861ccd15_5" rgba="0.490 0.678 0.8 1" pos="0 0 0.007" quat="0.5 0.5 -0.5 -0.5"/>
              <geom class="visual" name="VISUAL_ur_forearm_link_6" type="mesh" mesh="MESH_forearm_861ccd15_6" rgba="0.031 0.031 0.031 1" pos="0 0 0.007" quat="0.5 0.5 -0.5 -0.5"/>

              <body name="ur_wrist_1_link" pos="-0.3922 0 0.1333" quat="1 0 0 0">
                <inertial mass="1.37" diaginertia="0.0011986756140664695 0.0014236273687040747 0.0016550170172294559" pos="0.0 -0.01634 -0.0018" quat="0.617164970477703 0.3485939338997156 0.334307835150133 0.6211504969174605"/>
                <joint name="ur_wrist_1_joint" type="hinge" axis="0 0 1" range="-6.283185307179586 6.283185307179586"/>
                <geom class="collision" name="COLLISION_ur_wrist_1_link_0" type="mesh" mesh="MESH_wrist1_2df87b9f" pos="0 0 -0.127" quat="0.7071067811865476 0.7071067811865475 0 0"/>
                <geom class="visual" name="VISUAL_ur_wrist_1_link_0" type="mesh" mesh="MESH_wrist1_1e3ee180_0" rgba="0.278 0.278 0.278 1" pos="0 0 -0.127" quat="0.7071067811865476 0.7071067811865475 0 0"/>
                <geom class="visual" name="VISUAL_ur_wrist_1_link_1" type="mesh" mesh="MESH_wrist1_1e3ee180_1" rgba="0.490 0.678 0.8 1" pos="0 0 -0.127" quat="0.7071067811865476 0.7071067811865475 0 0"/>
                <geom class="visual" name="VISUAL_ur_wrist_1_link_2" type="mesh" mesh="MESH_wrist1_1e3ee180_2" rgba="0.031 0.031 0.031 1" pos="0 0 -0.127" quat="0.7071067811865476 0.7071067811865475 0 0"/>

                <body name="ur_wrist_2_link" pos="0 -0.0997 0" quat="0.7071067811140325 0.7071067812590626 0 0">
                  <inertial mass="1.3" diaginertia="0.0009581396620642861 0.001286066344108885 0.001356373993826829" pos="0.0 0.01634 -0.0018" quat="0.5288470911292525 -0.47465159334892915 -0.4440672234695894 0.5457388754481953"/>
                  <joint name="ur_wrist_2_joint" type="hinge" axis="0 0 1" range="-6.283185307179586 6.283185307179586"/>
                  <geom class="collision" name="COLLISION_ur_wrist_2_link_0" type="mesh" mesh="MESH_wrist2_e6869549" pos="0 0 -0.0997" quat="1 0 0 0"/>
                  <geom class="visual" name="VISUAL_ur_wrist_2_link_0" type="mesh" mesh="MESH_wrist2_bde41993_0" rgba="0.278 0.278 0.278 1" pos="0 0 -0.0997" quat="1 0 0 0"/>
                  <geom class="visual" name="VISUAL_ur_wrist_2_link_1" type="mesh" mesh="MESH_wrist2_bde41993_1" rgba="0.490 0.678 0.8 1" pos="0 0 -0.0997" quat="1 0 0 0"/>
                  <geom class="visual" name="VISUAL_ur_wrist_2_link_2" type="mesh" mesh="MESH_wrist2_bde41993_2" rgba="0.031 0.031 0.031 1" pos="0 0 -0.0997" quat="1 0 0 0"/>

                  <body name="ur_wrist_3_link" pos="0 0.0996 0" quat="0.7071067811140325 -0.7071067812590626 0 0">
                    <inertial mass="0.365" diaginertia="0.00018693802309626027 0.00018906920634770998 0.0002575727705560295" pos="0.0 0.0 -0.001159" quat="0.9998848543715624 -0.006732397405301183 0.0011178804501228406 0.013553714134353398"/>
                    <joint name="ur_wrist_3_joint" type="hinge" axis="0 0 1" range="-6.283185307179586 6.283185307179586"/>
                    <geom class="collision" name="COLLISION_ur_wrist_3_link_0" type="mesh" mesh="MESH_wrist3_21abe53b" pos="0 0 -0.0989" quat="0.7071067811865476 0.7071067811865475 0 0"/>
                    <geom class="visual" name="VISUAL_ur_wrist_3_link_0" type="mesh" mesh="MESH_wrist3_8e7adc5c_0" rgba="0.820 0.820 0.820 1" pos="0 0 -0.0989" quat="0.7071067811865476 0.7071067811865475 0 0"/>

                    <!-- 法兰盘 -> 夹爪和相机的挂载点 -->
                    <body name="ur_flange" pos="0 0 0" quat="0.5 -0.5 -0.5 -0.5">
                      <body name="ur_tool0" pos="0 0 0" quat="0.5 0.5 0.5 0.5">
                        <!-- 夹爪挂载点 -->
                        <site name="gripper_mount" pos="0 0 0.006" quat="1 0 0 0"/>
                        <!-- TCP site -->
                        <site name="_tcp" pos="0 0 0.16" quat="1 0 0 0"/>
                      </body>
                    </body>
                  </body>
                </body>
              </body>
            </body>
          </body>
        </body>
      </body>
      <body name="ur_base" pos="0 0 0" quat="6.123233995736766e-17 0 0 1"/>
    </body>
  </worldbody>

  <!-- Position actuators for joint incremental control -->
  <actuator>
    <position name="ur_shoulder_pan_joint_ACTUATOR"  joint="ur_shoulder_pan_joint"  kp="2000" dampratio="1.0" ctrlrange="-6.2832 6.2832"/>
    <position name="ur_shoulder_lift_joint_ACTUATOR"  joint="ur_shoulder_lift_joint"  kp="2000" dampratio="1.0" ctrlrange="-6.2832 6.2832"/>
    <position name="ur_elbow_joint_ACTUATOR"           joint="ur_elbow_joint"         kp="2000" dampratio="1.0" ctrlrange="-3.1416 3.1416"/>
    <position name="ur_wrist_1_joint_ACTUATOR"          joint="ur_wrist_1_joint"        kp="500"  dampratio="1.0" ctrlrange="-6.2832 6.2832"/>
    <position name="ur_wrist_2_joint_ACTUATOR"          joint="ur_wrist_2_joint"        kp="500"  dampratio="1.0" ctrlrange="-6.2832 6.2832"/>
    <position name="ur_wrist_3_joint_ACTUATOR"          joint="ur_wrist_3_joint"        kp="500"  dampratio="1.0" ctrlrange="-6.2832 6.2832"/>
  </actuator>

  <sensor>
    <force name="ur_ft_frame_SENSOR_FORCE" site="_tcp"/>
    <torque name="ur_ft_frame_SENSOR_TORQUE" site="_tcp"/>
  </sensor>

  <contact>
    <exclude body1="ur_base_link_inertia" body2="ur_shoulder_link"/>
    <exclude body1="ur_shoulder_link" body2="ur_upper_arm_link"/>
    <exclude body1="ur_upper_arm_link" body2="ur_forearm_link"/>
    <exclude body1="ur_forearm_link" body2="ur_wrist_1_link"/>
    <exclude body1="ur_wrist_1_link" body2="ur_wrist_2_link"/>
    <exclude body1="ur_wrist_2_link" body2="ur_wrist_3_link"/>
  </contact>

  <keyframe>
    <key name="home" qpos="0.0 -1.5708 1.5708 -1.5708 -1.5708 0.0"/>
  </keyframe>
</mujoco>
