<mujoco model="peg_in_slot_scene">
  <compiler angle="radian" meshdir="../ur5/meshes"/>

  <visual>
    <global offwidth="640" offheight="480"/>
    <quality shadowsize="4096"/>
    <headlight diffuse="0.6 0.6 0.6" ambient="0.1 0.1 0.1"/>
  </visual>

  <statistic center="0.45 0 0.3" extent="0.8"/>

  <asset>
    <texture name="skybox" type="skybox" builtin="gradient" rgb1="0.3 0.5 0.7" rgb2="0 0 0" width="512" height="3072"/>
  </asset>

<!--
  UR5e 完整模型: 机械臂 + Robotiq 85 夹爪 + RealSense D435 手眼相机
  所有组件在同一文件中，用于 scene 的 <include>
  
  关节:
    ur_shoulder_pan_joint, ur_shoulder_lift_joint, ur_elbow_joint,
    ur_wrist_1_joint, ur_wrist_2_joint, ur_wrist_3_joint (6个arm关节)
    robotiq_85_left_knuckle_joint (主动夹爪关节)
  
  Actuator 全部使用 position 模式，支持关节位置增量控制
-->  <!-- ========== Assets: 所有 mesh ========== -->
  <asset>
    <!-- Base -->
    <mesh name="MESH_base_bd1b2dd6" file="base_bd1b2dd6.stl"/>
    <mesh name="MESH_base_b81001a2_0" file="base_b81001a2_0.obj"/>
    <mesh name="MESH_base_b81001a2_1" file="base_b81001a2_1.obj"/>
    <!-- Shoulder -->
    <mesh name="MESH_shoulder_661339ad" file="shoulder_661339ad.stl"/>
    <mesh name="MESH_shoulder_0fe2d913_0" file="shoulder_0fe2d913_0.obj"/>
    <mesh name="MESH_shoulder_0fe2d913_1" file="shoulder_0fe2d913_1.obj"/>
    <mesh name="MESH_shoulder_0fe2d913_2" file="shoulder_0fe2d913_2.obj"/>
    <!-- Upper arm -->
    <mesh name="MESH_upperarm_d0455716" file="upperarm_d0455716.stl"/>
    <mesh name="MESH_upperarm_12b51e98_0" file="upperarm_12b51e98_0.obj"/>
    <mesh name="MESH_upperarm_12b51e98_1" file="upperarm_12b51e98_1.obj"/>
    <mesh name="MESH_upperarm_12b51e98_2" file="upperarm_12b51e98_2.obj"/>
    <mesh name="MESH_upperarm_12b51e98_3" file="upperarm_12b51e98_3.obj"/>
    <mesh name="MESH_upperarm_12b51e98_4" file="upperarm_12b51e98_4.obj"/>
    <mesh name="MESH_upperarm_12b51e98_5" file="upperarm_12b51e98_5.obj"/>
    <mesh name="MESH_upperarm_12b51e98_6" file="upperarm_12b51e98_6.obj"/>
    <mesh name="MESH_upperarm_12b51e98_7" file="upperarm_12b51e98_7.obj"/>
    <!-- Forearm -->
    <mesh name="MESH_forearm_98bdcf8e" file="forearm_98bdcf8e.stl"/>
    <mesh name="MESH_forearm_861ccd15_0" file="forearm_861ccd15_0.obj"/>
    <mesh name="MESH_forearm_861ccd15_1" file="forearm_861ccd15_1.obj"/>
    <mesh name="MESH_forearm_861ccd15_2" file="forearm_861ccd15_2.obj"/>
    <mesh name="MESH_forearm_861ccd15_3" file="forearm_861ccd15_3.obj"/>
    <mesh name="MESH_forearm_861ccd15_4" file="forearm_861ccd15_4.obj"/>
    <mesh name="MESH_forearm_861ccd15_5" file="forearm_861ccd15_5.obj"/>
    <mesh name="MESH_forearm_861ccd15_6" file="forearm_861ccd15_6.obj"/>
    <!-- Wrist 1 -->
    <mesh name="MESH_wrist1_2df87b9f" file="wrist1_2df87b9f.stl"/>
    <mesh name="MESH_wrist1_1e3ee180_0" file="wrist1_1e3ee180_0.obj"/>
    <mesh name="MESH_wrist1_1e3ee180_1" file="wrist1_1e3ee180_1.obj"/>
    <mesh name="MESH_wrist1_1e3ee180_2" file="wrist1_1e3ee180_2.obj"/>
    <!-- Wrist 2 -->
    <mesh name="MESH_wrist2_e6869549" file="wrist2_e6869549.stl"/>
    <mesh name="MESH_wrist2_bde41993_0" file="wrist2_bde41993_0.obj"/>
    <mesh name="MESH_wrist2_bde41993_1" file="wrist2_bde41993_1.obj"/>
    <mesh name="MESH_wrist2_bde41993_2" file="wrist2_bde41993_2.obj"/>
    <!-- Wrist 3 -->
    <mesh name="MESH_wrist3_21abe53b" file="wrist3_21abe53b.stl"/>
    <mesh name="MESH_wrist3_8e7adc5c_0" file="wrist3_8e7adc5c_0.obj"/>
    <!-- Shelf / adapter -->
    <mesh name="MESH_RealSense_D435_Shelf_d359ca29" file="RealSense_D435_Shelf_d359ca29.STL"/>
    <mesh name="MESH_ur_to_robotiq_adapter_c1f8affd" file="ur_to_robotiq_adapter_c1f8affd.stl"/>
    <mesh name="MESH_ur_to_robotiq_adapter_e07b68cf_0" file="ur_to_robotiq_adapter_e07b68cf_0.obj"/>
    <mesh name="MESH_ur_to_robotiq_adapter_e07b68cf_1" file="ur_to_robotiq_adapter_e07b68cf_1.obj"/>
    <!-- Gripper base -->
    <mesh name="MESH_robotiq_base_e14b1363" file="robotiq_base_e14b1363.stl"/>
    <mesh name="MESH_robotiq_base_ba4c22e7_0" file="robotiq_base_ba4c22e7_0.obj"/>
    <mesh name="MESH_robotiq_base_ba4c22e7_1" file="robotiq_base_ba4c22e7_1.obj"/>
    <!-- Left finger -->
    <mesh name="MESH_left_knuckle_51d3a21e" file="left_knuckle_51d3a21e.stl"/>
    <mesh name="MESH_left_knuckle_ac6d7519_0" file="left_knuckle_ac6d7519_0.obj"/>
    <mesh name="MESH_left_finger_1b48fede" file="left_finger_1b48fede.stl"/>
    <mesh name="MESH_left_finger_e1ea88f9_0" file="left_finger_e1ea88f9_0.obj"/>
    <mesh name="MESH_left_finger_e1ea88f9_1" file="left_finger_e1ea88f9_1.obj"/>
    <mesh name="MESH_left_finger_tip_c9609174" file="left_finger_tip_c9609174.stl"/>
    <mesh name="MESH_left_finger_tip_4c918411_0" file="left_finger_tip_4c918411_0.obj"/>
    <mesh name="MESH_left_finger_tip_4c918411_1" file="left_finger_tip_4c918411_1.obj"/>
    <!-- Right finger -->
    <mesh name="MESH_right_knuckle_8dc62fad" file="right_knuckle_8dc62fad.stl"/>
    <mesh name="MESH_right_knuckle_922d025b_0" file="right_knuckle_922d025b_0.obj"/>
    <mesh name="MESH_right_finger_df3e86a5" file="right_finger_df3e86a5.stl"/>
    <mesh name="MESH_right_finger_12094dbb_0" file="right_finger_12094dbb_0.obj"/>
    <mesh name="MESH_right_finger_12094dbb_1" file="right_finger_12094dbb_1.obj"/>
    <mesh name="MESH_right_finger_tip_8abbbc6d" file="right_finger_tip_8abbbc6d.stl"/>
    <mesh name="MESH_right_finger_tip_5aafdc4f_0" file="right_finger_tip_5aafdc4f_0.obj"/>
    <mesh name="MESH_right_finger_tip_5aafdc4f_1" file="right_finger_tip_5aafdc4f_1.obj"/>
    <!-- Inner knuckles -->
    <mesh name="MESH_left_inner_knuckle_11ecd5a1" file="left_inner_knuckle_11ecd5a1.stl"/>
    <mesh name="MESH_left_inner_knuckle_d6e20ced_0" file="left_inner_knuckle_d6e20ced_0.obj"/>
    <mesh name="MESH_left_inner_knuckle_d6e20ced_1" file="left_inner_knuckle_d6e20ced_1.obj"/>
    <mesh name="MESH_right_inner_knuckle_2c3a72a4" file="right_inner_knuckle_2c3a72a4.stl"/>
    <mesh name="MESH_right_inner_knuckle_8d05a49d_0" file="right_inner_knuckle_8d05a49d_0.obj"/>
    <mesh name="MESH_right_inner_knuckle_8d05a49d_1" file="right_inner_knuckle_8d05a49d_1.obj"/>
    <!-- D435 camera -->
    <mesh name="MESH_d435_6743a526_0"  file="d435_6743a526_0.obj"/>
    <mesh name="MESH_d435_6743a526_1"  file="d435_6743a526_1.obj"/>
    <mesh name="MESH_d435_6743a526_2"  file="d435_6743a526_2.obj"/>
    <mesh name="MESH_d435_6743a526_3"  file="d435_6743a526_3.obj"/>
    <mesh name="MESH_d435_6743a526_4"  file="d435_6743a526_4.obj"/>
    <mesh name="MESH_d435_6743a526_5"  file="d435_6743a526_5.obj"/>
    <mesh name="MESH_d435_6743a526_6"  file="d435_6743a526_6.obj"/>
    <mesh name="MESH_d435_6743a526_7"  file="d435_6743a526_7.obj"/>
    <mesh name="MESH_d435_6743a526_8"  file="d435_6743a526_8.obj"/>
    <mesh name="MESH_d435_6743a526_9"  file="d435_6743a526_9.obj"/>
    <mesh name="MESH_d435_6743a526_10" file="d435_6743a526_10.obj"/>
    <mesh name="MESH_d435_6743a526_11" file="d435_6743a526_11.obj"/>
    <mesh name="MESH_d435_6743a526_12" file="d435_6743a526_12.obj"/>
    <mesh name="MESH_d435_6743a526_13" file="d435_6743a526_13.obj"/>
    <mesh name="MESH_d435_6743a526_14" file="d435_6743a526_14.obj"/>
    <mesh name="MESH_d435_6743a526_15" file="d435_6743a526_15.obj"/>
    <mesh name="MESH_d435_6743a526_16" file="d435_6743a526_16.obj"/>
    <mesh name="MESH_d435_6743a526_17" file="d435_6743a526_17.obj"/>
  </asset>

  <!-- ========== Defaults ========== -->
  <default>
    <default class="visual">
      <geom contype="0" conaffinity="0" group="2"/>
    </default>
    <default class="collision">
      <geom contype="1" conaffinity="1" group="3" condim="4"/>
    </default>
  </default>

  <!-- ========== Worldbody: 完整机器人 ========== -->
  

  <!-- ========== Tendons ========== -->
  <tendon>
    <fixed name="robotiq_knuckle_tendon">
      <joint joint="robotiq_85_left_knuckle_joint" coef="0.5"/>
      <joint joint="robotiq_85_right_knuckle_joint" coef="-0.5"/>
    </fixed>
  </tendon>

  <!-- ========== Contact exclusions ========== -->
  <contact>
    <exclude body1="ur_base_link_inertia" body2="ur_shoulder_link"/>
    <exclude body1="ur_shoulder_link" body2="ur_upper_arm_link"/>
    <exclude body1="ur_upper_arm_link" body2="ur_forearm_link"/>
    <exclude body1="ur_forearm_link" body2="ur_wrist_1_link"/>
    <exclude body1="ur_wrist_1_link" body2="ur_wrist_2_link"/>
    <exclude body1="ur_wrist_2_link" body2="ur_wrist_3_link"/>
    <exclude body1="robotiq_85_base_link" body2="robotiq_85_left_knuckle_link"/>
    <exclude body1="robotiq_85_base_link" body2="robotiq_85_right_knuckle_link"/>
    <exclude body1="robotiq_85_base_link" body2="robotiq_85_left_inner_knuckle_link"/>
    <exclude body1="robotiq_85_base_link" body2="robotiq_85_right_inner_knuckle_link"/>
    <exclude body1="robotiq_85_left_finger_link" body2="robotiq_85_left_finger_tip_link"/>
    <exclude body1="robotiq_85_right_finger_link" body2="robotiq_85_right_finger_tip_link"/>
    <exclude body1="robotiq_85_left_finger_tip_link" body2="robotiq_85_left_inner_knuckle_link"/>
    <exclude body1="robotiq_85_right_finger_tip_link" body2="robotiq_85_right_inner_knuckle_link"/>
  </contact>

  <!-- ========== Actuators (全 position 模式) ========== -->
  <actuator>
    <!-- Arm joints -->
    <position name="ur_shoulder_pan_joint_ACTUATOR"  joint="ur_shoulder_pan_joint"  kp="2000" dampratio="1.0" ctrlrange="-6.2832 6.2832"/>
    <position name="ur_shoulder_lift_joint_ACTUATOR"  joint="ur_shoulder_lift_joint"  kp="2000" dampratio="1.0" ctrlrange="-6.2832 6.2832"/>
    <position name="ur_elbow_joint_ACTUATOR"           joint="ur_elbow_joint"         kp="2000" dampratio="1.0" ctrlrange="-3.1416 3.1416"/>
    <position name="ur_wrist_1_joint_ACTUATOR"          joint="ur_wrist_1_joint"        kp="500"  dampratio="1.0" ctrlrange="-6.2832 6.2832"/>
    <position name="ur_wrist_2_joint_ACTUATOR"          joint="ur_wrist_2_joint"        kp="500"  dampratio="1.0" ctrlrange="-6.2832 6.2832"/>
    <position name="ur_wrist_3_joint_ACTUATOR"          joint="ur_wrist_3_joint"        kp="500"  dampratio="1.0" ctrlrange="-6.2832 6.2832"/>
    <!-- Gripper joint -->
    <position name="robotiq_85_left_knuckle_joint_ACTUATOR" joint="robotiq_85_left_knuckle_joint" kp="10" dampratio="1.0" ctrlrange="0.0 0.7929"/>
  </actuator>

  <!-- ========== Equality constraints ========== -->
  <equality>
    <connect anchor="-0.018 0 0.0065" body1="robotiq_85_left_finger_tip_link" body2="robotiq_85_left_inner_knuckle_link" solimp="0.95 0.99 0.001" solref="0.005 1"/>
    <connect anchor="0.018 0 0.0065" body1="robotiq_85_right_finger_tip_link" body2="robotiq_85_right_inner_knuckle_link" solimp="0.95 0.99 0.001" solref="0.005 1"/>
    <joint joint1="robotiq_85_left_knuckle_joint" joint2="robotiq_85_right_knuckle_joint" polycoef="0.0 -1.0 0.0 0.0 0.0"/>
  </equality>

  <!-- ========== Sensors ========== -->
  <sensor>
    <force name="ur_ft_frame_SENSOR_FORCE" site="_tcp"/>
    <torque name="ur_ft_frame_SENSOR_TORQUE" site="_tcp"/>
  </sensor>

  <!-- ========== Keyframes ========== -->
  <keyframe>
    <key name="home" qpos="0.0 -1.5708 1.5708 -1.5708 -1.5708 0.0 0.0"/>
  </keyframe>

  <worldbody>
    <geom name="floor" type="plane" size="0 0 0.05" rgba="0.4 0.4 0.45 1"/>
    <light name="overhead" pos="0 0 2" dir="0 0 -1" directional="true"/>

    <body name="table_top" pos="0.45 0 0.12">
      <geom name="table_surface" type="box" size="0.40 0.35 0.01" pos="0 0 0.01" rgba="0.35 0.3 0.25 1"/>
      <geom name="table_leg1" type="box" size="0.02 0.02 0.3" pos="-0.35 0.3 -0.3" rgba="0.3 0.25 0.2 1"/>
      <geom name="table_leg2" type="box" size="0.02 0.02 0.3" pos="0.35 0.3 -0.3" rgba="0.3 0.25 0.2 1"/>
      <geom name="table_leg3" type="box" size="0.02 0.02 0.3" pos="-0.35 -0.3 -0.3" rgba="0.3 0.25 0.2 1"/>
      <geom name="table_leg4" type="box" size="0.02 0.02 0.3" pos="0.35 -0.3 -0.3" rgba="0.3 0.25 0.2 1"/>
    </body>

    <!-- 凸轴 -->
    <body name="peg" pos="0.38 0 0.162">
      <freejoint name="peg_joint"/>
      <geom name="peg_body" type="cylinder" size="0.015 0.03" pos="0 0 0.015" rgba="0.9 0.5 0.1 1" friction="0.6 0.4 0.2"/>
      <inertial mass="0.06" diaginertia="1e-5 1e-5 1e-5" pos="0 0 0.03"/>
      <geom name="peg_tip" type="cylinder" size="0.008 0.01" pos="0 0 0.055" rgba="0.95 0.6 0.2 1" friction="0.4 0.3 0.1"/>
      <site name="peg_tip_site" pos="0 0 0.065" size="0.003"/>
      <site name="peg_grasp_site" pos="0 0 0.04" size="0.005"/>
    </body>

    <body name="slot_block" pos="0.52 0 0.152">
      <freejoint name="slot_block_joint"/>
      <inertial mass="0.1" diaginertia="5e-5 5e-5 5e-5" pos="0 0 0"/>
      <geom name="slot_base" type="box" size="0.03 0.03 0.02" pos="0 0 0" rgba="0.5 0.5 0.55 1" friction="0.7 0.5 0.3"/>
      <geom name="slot_wall_top" type="box" size="0.012 0.006 0.015" pos="0 0.024 0.005" rgba="0.5 0.5 0.55 1" friction="0.7 0.5 0.3"/>
      <geom name="slot_wall_bottom" type="box" size="0.012 0.006 0.015" pos="0 -0.024 0.005" rgba="0.5 0.5 0.55 1" friction="0.7 0.5 0.3"/>
      <geom name="slot_wall_left" type="box" size="0.006 0.018 0.015" pos="-0.024 0 0.005" rgba="0.5 0.5 0.55 1" friction="0.7 0.5 0.3"/>
      <geom name="slot_wall_right" type="box" size="0.006 0.018 0.015" pos="0.024 0 0.005" rgba="0.5 0.5 0.55 1" friction="0.7 0.5 0.3"/>
      <site name="slot_bottom" pos="0 0 -0.005" size="0.003"/>
      <site name="slot_top" pos="0 0 0.025" size="0.003"/>
      <site name="slot_center" pos="0 0 0.01" size="0.005"/>
    </body>
<body name="ur_base_link" pos="0 0 0.1" quat="1 0 0 0">
      <!-- Base -->
      <body name="ur_base_link_inertia" pos="0 0 0" quat="6.123233995736766e-17 0 0 1">
        <inertial mass="4.0" diaginertia="0.00443333156 0.00443333156 0.0072" pos="0 0 0" quat="1 0 0 0"/>
        <geom class="collision" type="mesh" mesh="MESH_base_bd1b2dd6"/>
        <geom class="visual" type="mesh" mesh="MESH_base_b81001a2_0" rgba="0.278 0.278 0.278 1"/>
        <geom class="visual" type="mesh" mesh="MESH_base_b81001a2_1" rgba="0.031 0.031 0.031 1"/>

        <!-- Shoulder -->
        <body name="ur_shoulder_link" pos="0 0 0.1625" quat="1 0 0 0">
          <inertial mass="3.761" diaginertia="0.006024775831167757 0.0070003048838239885 0.007030789285008251" pos="0.0 -0.00193 -0.02561" quat="0.20206705998679322 0.6747312134749398 0.365097644892179 -0.6087777940473136"/>
          <joint name="ur_shoulder_pan_joint" type="hinge" axis="0 0 1" range="-6.283185307179586 6.283185307179586"/>
          <geom class="collision" type="mesh" mesh="MESH_shoulder_661339ad"/>
          <geom class="visual" type="mesh" mesh="MESH_shoulder_0fe2d913_0" rgba="0.278 0.278 0.278 1"/>
          <geom class="visual" type="mesh" mesh="MESH_shoulder_0fe2d913_1" rgba="0.031 0.031 0.031 1"/>
          <geom class="visual" type="mesh" mesh="MESH_shoulder_0fe2d913_2" rgba="0.490 0.678 0.8 1"/>

          <!-- Upper arm -->
          <body name="ur_upper_arm_link" pos="0 0 0" quat="0.7071067811140325 0.7071067812590626 0 0">
            <inertial mass="8.058" diaginertia="0.015058840753982044 0.3324720677719464 0.3338808714740716" pos="-0.2125 0.0 0.11336" quat="0.7066521546519151 0.7075611104882223 5.365436380901162e-05 -6.611874721869904e-05"/>
            <joint name="ur_shoulder_lift_joint" type="hinge" axis="0 0 1" range="-6.283185307179586 6.283185307179586"/>
            <geom class="collision" type="mesh" mesh="MESH_upperarm_d0455716" pos="0 0 0.138" quat="0.5 0.5 -0.5 -0.5"/>
            <geom class="visual" type="mesh" mesh="MESH_upperarm_12b51e98_0" rgba="0.490 0.678 0.8 1" pos="0 0 0.138" quat="0.5 0.5 -0.5 -0.5"/>
            <geom class="visual" type="mesh" mesh="MESH_upperarm_12b51e98_1" rgba="0.278 0.278 0.278 1" pos="0 0 0.138" quat="0.5 0.5 -0.5 -0.5"/>
            <geom class="visual" type="mesh" mesh="MESH_upperarm_12b51e98_2" rgba="0.031 0.031 0.031 1" pos="0 0 0.138" quat="0.5 0.5 -0.5 -0.5"/>
            <geom class="visual" type="mesh" mesh="MESH_upperarm_12b51e98_3" rgba="0.490 0.678 0.8 1" pos="0 0 0.138" quat="0.5 0.5 -0.5 -0.5"/>
            <geom class="visual" type="mesh" mesh="MESH_upperarm_12b51e98_4" rgba="0.820 0.820 0.820 1" pos="0 0 0.138" quat="0.5 0.5 -0.5 -0.5"/>
            <geom class="visual" type="mesh" mesh="MESH_upperarm_12b51e98_5" rgba="0.031 0.031 0.031 1" pos="0 0 0.138" quat="0.5 0.5 -0.5 -0.5"/>
            <geom class="visual" type="mesh" mesh="MESH_upperarm_12b51e98_6" rgba="0.278 0.278 0.278 1" pos="0 0 0.138" quat="0.5 0.5 -0.5 -0.5"/>
            <geom class="visual" type="mesh" mesh="MESH_upperarm_12b51e98_7" rgba="0.031 0.031 0.031 1" pos="0 0 0.138" quat="0.5 0.5 -0.5 -0.5"/>

            <!-- Forearm -->
            <body name="ur_forearm_link" pos="-0.425 0 0" quat="1 0 0 0">
              <inertial mass="2.846" diaginertia="0.003971028904819707 0.0785102224320644 0.07879270866311583" pos="-0.2422 0.0 0.0265" quat="0.6984488939206283 0.715600664432383 -0.006368275363090868 -0.006654074983260038"/>
              <joint name="ur_elbow_joint" type="hinge" axis="0 0 1" range="-3.141592653589793 3.141592653589793"/>
              <geom class="collision" type="mesh" mesh="MESH_forearm_98bdcf8e" pos="0 0 0.007" quat="0.5 0.5 -0.5 -0.5"/>
              <geom class="visual" type="mesh" mesh="MESH_forearm_861ccd15_0" rgba="0.278 0.278 0.278 1" pos="0 0 0.007" quat="0.5 0.5 -0.5 -0.5"/>
              <geom class="visual" type="mesh" mesh="MESH_forearm_861ccd15_1" rgba="0.278 0.278 0.278 1" pos="0 0 0.007" quat="0.5 0.5 -0.5 -0.5"/>
              <geom class="visual" type="mesh" mesh="MESH_forearm_861ccd15_2" rgba="0.031 0.031 0.031 1" pos="0 0 0.007" quat="0.5 0.5 -0.5 -0.5"/>
              <geom class="visual" type="mesh" mesh="MESH_forearm_861ccd15_3" rgba="0.820 0.820 0.820 1" pos="0 0 0.007" quat="0.5 0.5 -0.5 -0.5"/>
              <geom class="visual" type="mesh" mesh="MESH_forearm_861ccd15_4" rgba="0.031 0.031 0.031 1" pos="0 0 0.007" quat="0.5 0.5 -0.5 -0.5"/>
              <geom class="visual" type="mesh" mesh="MESH_forearm_861ccd15_5" rgba="0.490 0.678 0.8 1" pos="0 0 0.007" quat="0.5 0.5 -0.5 -0.5"/>
              <geom class="visual" type="mesh" mesh="MESH_forearm_861ccd15_6" rgba="0.031 0.031 0.031 1" pos="0 0 0.007" quat="0.5 0.5 -0.5 -0.5"/>

              <!-- Wrist 1 -->
              <body name="ur_wrist_1_link" pos="-0.3922 0 0.1333" quat="1 0 0 0">
                <inertial mass="1.37" diaginertia="0.0011986756140664695 0.0014236273687040747 0.0016550170172294559" pos="0.0 -0.01634 -0.0018" quat="0.617164970477703 0.3485939338997156 0.334307835150133 0.6211504969174605"/>
                <joint name="ur_wrist_1_joint" type="hinge" axis="0 0 1" range="-6.283185307179586 6.283185307179586"/>
                <geom class="collision" type="mesh" mesh="MESH_wrist1_2df87b9f" pos="0 0 -0.127" quat="0.7071067811865476 0.7071067811865475 0 0"/>
                <geom class="visual" type="mesh" mesh="MESH_wrist1_1e3ee180_0" rgba="0.278 0.278 0.278 1" pos="0 0 -0.127" quat="0.7071067811865476 0.7071067811865475 0 0"/>
                <geom class="visual" type="mesh" mesh="MESH_wrist1_1e3ee180_1" rgba="0.490 0.678 0.8 1" pos="0 0 -0.127" quat="0.7071067811865476 0.7071067811865475 0 0"/>
                <geom class="visual" type="mesh" mesh="MESH_wrist1_1e3ee180_2" rgba="0.031 0.031 0.031 1" pos="0 0 -0.127" quat="0.7071067811865476 0.7071067811865475 0 0"/>

                <!-- Wrist 2 -->
                <body name="ur_wrist_2_link" pos="0 -0.0997 0" quat="0.7071067811140325 0.7071067812590626 0 0">
                  <inertial mass="1.3" diaginertia="0.0009581396620642861 0.001286066344108885 0.001356373993826829" pos="0.0 0.01634 -0.0018" quat="0.5288470911292525 -0.47465159334892915 -0.4440672234695894 0.5457388754481953"/>
                  <joint name="ur_wrist_2_joint" type="hinge" axis="0 0 1" range="-6.283185307179586 6.283185307179586"/>
                  <geom class="collision" type="mesh" mesh="MESH_wrist2_e6869549" pos="0 0 -0.0997"/>
                  <geom class="visual" type="mesh" mesh="MESH_wrist2_bde41993_0" rgba="0.278 0.278 0.278 1" pos="0 0 -0.0997"/>
                  <geom class="visual" type="mesh" mesh="MESH_wrist2_bde41993_1" rgba="0.490 0.678 0.8 1" pos="0 0 -0.0997"/>
                  <geom class="visual" type="mesh" mesh="MESH_wrist2_bde41993_2" rgba="0.031 0.031 0.031 1" pos="0 0 -0.0997"/>

                  <!-- Wrist 3 -->
                  <body name="ur_wrist_3_link" pos="0 0.0996 0" quat="0.7071067811140325 -0.7071067812590626 0 0">
                    <inertial mass="0.365" diaginertia="0.00018693802309626027 0.00018906920634770998 0.0002575727705560295" pos="0.0 0.0 -0.001159" quat="0.9998848543715624 -0.006732397405301183 0.0011178804501228406 0.013553714134353398"/>
                    <joint name="ur_wrist_3_joint" type="hinge" axis="0 0 1" range="-6.283185307179586 6.283185307179586"/>
                    <geom class="collision" type="mesh" mesh="MESH_wrist3_21abe53b" pos="0 0 -0.0989" quat="0.7071067811865476 0.7071067811865475 0 0"/>
                    <geom class="visual" type="mesh" mesh="MESH_wrist3_8e7adc5c_0" rgba="0.820 0.820 0.820 1" pos="0 0 -0.0989" quat="0.7071067811865476 0.7071067811865475 0 0"/>

                    <!-- Flange -->
                    <body name="ur_flange" pos="0 0 0" quat="0.5 -0.5 -0.5 -0.5">
                      <body name="ur_tool0" pos="0 0 0" quat="0.5 0.5 0.5 0.5">

                        <!-- ===== Realsense Shelf (camera + gripper mount) ===== -->
                        <body name="realsense_shelf" pos="0 0 0" quat="6.123233995736766e-17 0 0 1">
                          <inertial mass="0.038" diaginertia="6.673e-05 8.5e-06 7.517e-05" pos="0.0 0.044 0.0015" quat="1 0 0 0"/>
                          <geom class="collision" type="mesh" mesh="MESH_RealSense_D435_Shelf_d359ca29"/>
                          <geom class="visual" type="mesh" mesh="MESH_RealSense_D435_Shelf_d359ca29" rgba="0.7 0.7 0.7 1"/>

                          <!-- Camera mount side -->
                          <body name="realsense_shelf_child_side" pos="0 0 0.006" quat="1 0 0 0">

                            <!-- ===== Robotiq 85 Gripper ===== -->
                            <body name="robotiq_ur_to_robotiq_link" pos="0 0 0" quat="1 0 0 0">
                              <inertial mass="0.01" diaginertia="4.4e-05 2.7e-05 2.7e-05" pos="0 0 0" quat="1 0 0 0"/>
                              <geom class="collision" type="mesh" mesh="MESH_ur_to_robotiq_adapter_c1f8affd"/>
                              <geom class="visual" type="mesh" mesh="MESH_ur_to_robotiq_adapter_e07b68cf_0" rgba="0.039 0.039 0.039 1"/>
                              <geom class="visual" type="mesh" mesh="MESH_ur_to_robotiq_adapter_e07b68cf_1" rgba="0.298 0.298 0.298 1"/>

                              <body name="robotiq_ur_to_g2f85_child_side" pos="0 0 0.011" quat="1 0 0 0">

                                <!-- Gripper base -->
                                <body name="robotiq_85_base_link" pos="0 0 0" quat="1 0 0 0">
                                  <inertial mass="0.66320197" diaginertia="0.00039462722067250294 0.0005161781480017798 0.0005880226313257172" pos="0.0 2.274e-05 0.03232288" quat="0.5005192813628906 -0.49947997687615325 0.49968467889977636 -0.5003153239274212"/>
                                  <geom class="collision" type="mesh" mesh="MESH_robotiq_base_e14b1363"/>
                                  <geom class="visual" type="mesh" mesh="MESH_robotiq_base_ba4c22e7_0" rgba="0.031 0.031 0.031 1"/>
                                  <geom class="visual" type="mesh" mesh="MESH_robotiq_base_ba4c22e7_1" rgba="0.8 0.8 0.8 1"/>

                                  <!-- Left finger chain -->
                                  <body name="robotiq_85_left_knuckle_link" pos="0.03060114 0 0.05490452" quat="1 0 0 0">
                                    <inertial mass="0.01384773208" diaginertia="3.4500845003981836e-07 2.238671549960182e-06 2.31944e-06" pos="0.01213197 0.0002 -0.00058647" quat="0.7067650957173783 -0.706765095717382 -0.02197952400764002 0.021979524007640125"/>
                                    <joint name="robotiq_85_left_knuckle_joint" type="hinge" axis="0 -1 0" range="0.0 0.8"/>
                                    <geom class="collision" type="mesh" mesh="MESH_left_knuckle_51d3a21e"/>
                                    <geom class="visual" type="mesh" mesh="MESH_left_knuckle_ac6d7519_0" rgba="0.8 0.8 0.8 1"/>

                                    <body name="robotiq_85_left_finger_link" pos="0.03152616 0 -0.00376347" quat="1 0 0 0">
                                      <inertial mass="0.04260376752" diaginertia="4.6822750126340444e-06 1.183208e-05 1.4372364987365957e-05" pos="0.00346899 -0.00079447 0.01867121" quat="0.620317559743575 0 -0.7843507666049523 0"/>
                                      <geom class="collision" type="mesh" mesh="MESH_left_finger_1b48fede"/>
                                      <geom class="visual" type="mesh" mesh="MESH_left_finger_e1ea88f9_0" rgba="0.8 0.8 0.8 1"/>
                                      <geom class="visual" type="mesh" mesh="MESH_left_finger_e1ea88f9_1" rgba="0.031 0.031 0.031 1"/>

                                      <body name="robotiq_85_left_finger_tip_link" pos="0.00563134 0 0.04718515" quat="1 0 0 0">
                                        <inertial mass="0.04268588744" diaginertia="2.6440466428387786e-06 1.197888e-05 1.206531335716122e-05" pos="-0.01456706 -0.0008 0.01649701" quat="0.0 0.5431343521286145 0.0 0.8396458036206875"/>
                                        <joint name="robotiq_85_left_finger_tip_joint" type="hinge" axis="0 -1 0"/>
                                        <geom class="collision" type="mesh" mesh="MESH_left_finger_tip_c9609174"
                                          margin="0.001" solmix="10" solref="-3000 -500" solimp="0.95 0.99 0.001 0.5 2" priority="10" friction="5 5 0.02"/>
                                        <geom class="visual" type="mesh" mesh="MESH_left_finger_tip_4c918411_0" rgba="0.031 0.031 0.031 1"/>
                                        <geom class="visual" type="mesh" mesh="MESH_left_finger_tip_4c918411_1" rgba="0.8 0.8 0.8 1"/>
                                      </body>
                                    </body>
                                  </body>

                                  <!-- Right finger chain -->
                                  <body name="robotiq_85_right_knuckle_link" pos="-0.03060114 0 0.05490452" quat="1 0 0 0">
                                    <inertial mass="0.01384773208" diaginertia="3.4500845003981836e-07 2.238671549960182e-06 2.31944e-06" pos="-0.01213197 0.0002 -0.00058647" quat="0.7067650957173783 0.706765095717382 0.02197952400764002 0.021979524007640125"/>
                                    <joint name="robotiq_85_right_knuckle_joint" type="hinge" axis="0 -1 0" range="-0.8 0.0"/>
                                    <geom class="collision" type="mesh" mesh="MESH_right_knuckle_8dc62fad"/>
                                    <geom class="visual" type="mesh" mesh="MESH_right_knuckle_922d025b_0" rgba="0.8 0.8 0.8 1"/>

                                    <body name="robotiq_85_right_finger_link" pos="-0.03152616 0 -0.00376347" quat="1 0 0 0">
                                      <inertial mass="0.04260376752" diaginertia="4.6822750126340444e-06 1.183208e-05 1.4372364987365957e-05" pos="-0.00346899 -5.53e-06 0.01867121" quat="0 0.620317559743575 0 0.7843507666049523"/>
                                      <geom class="collision" type="mesh" mesh="MESH_right_finger_df3e86a5"/>
                                      <geom class="visual" type="mesh" mesh="MESH_right_finger_12094dbb_0" rgba="0.8 0.8 0.8 1"/>
                                      <geom class="visual" type="mesh" mesh="MESH_right_finger_12094dbb_1" rgba="0.031 0.031 0.031 1"/>

                                      <body name="robotiq_85_right_finger_tip_link" pos="-0.00563134 0 0.04718515" quat="1 0 0 0">
                                        <inertial mass="0.04268588744" diaginertia="2.6440466428387786e-06 1.197888e-05 1.206531335716122e-05" pos="0.01456706 5e-05 0.01649701" quat="0.5431343521286145 0 -0.8396458036206876 0"/>
                                        <joint name="robotiq_85_right_finger_tip_joint" type="hinge" axis="0 -1 0"/>
                                        <geom class="collision" type="mesh" mesh="MESH_right_finger_tip_8abbbc6d"
                                          margin="0.001" solmix="10" solref="-3000 -500" solimp="0.95 0.99 0.001 0.5 2" priority="10" friction="5 5 0.02"/>
                                        <geom class="visual" type="mesh" mesh="MESH_right_finger_tip_5aafdc4f_0" rgba="0.031 0.031 0.031 1"/>
                                        <geom class="visual" type="mesh" mesh="MESH_right_finger_tip_5aafdc4f_1" rgba="0.8 0.8 0.8 1"/>
                                      </body>
                                    </body>
                                  </body>

                                  <!-- Inner knuckles -->
                                  <body name="robotiq_85_left_inner_knuckle_link" pos="0.0127 0 0.06142" quat="1 0 0 0">
                                    <inertial mass="0.02969376448" diaginertia="4.887117939453948e-06 8.69056e-06 1.287568206054605e-05" pos="0.01897699 0.00015001 0.02247101" quat="0.42240861350400083 0 -0.9064055180975167 0"/>
                                    <joint name="robotiq_85_left_inner_knuckle_joint" type="hinge" axis="0 -1 0"/>
                                    <geom class="collision" type="mesh" mesh="MESH_left_inner_knuckle_11ecd5a1"/>
                                    <geom class="visual" type="mesh" mesh="MESH_left_inner_knuckle_d6e20ced_0" rgba="0.031 0.031 0.031 1"/>
                                    <geom class="visual" type="mesh" mesh="MESH_left_inner_knuckle_d6e20ced_1" rgba="0.8 0.8 0.8 1"/>
                                  </body>

                                  <body name="robotiq_85_right_inner_knuckle_link" pos="-0.0127 0 0.06142" quat="1 0 0 0">
                                    <inertial mass="0.02969376448" diaginertia="4.880756583548092e-06 8.69056e-06 1.288204341645191e-05" pos="-0.01926824 5.001e-05 0.02222178" quat="0 0.41391107378742875 0 0.9103173199473564"/>
                                    <joint name="robotiq_85_right_inner_knuckle_joint" type="hinge" axis="0 -1 0"/>
                                    <geom class="collision" type="mesh" mesh="MESH_right_inner_knuckle_2c3a72a4"/>
                                    <geom class="visual" type="mesh" mesh="MESH_right_inner_knuckle_8d05a49d_0" rgba="0.031 0.031 0.031 1"/>
                                    <geom class="visual" type="mesh" mesh="MESH_right_inner_knuckle_8d05a49d_1" rgba="0.8 0.8 0.8 1"/>
                                  </body>

                                  <!-- TCP at fingertip center -->
                                  <body name="_tcp" pos="0 0 0.12" quat="1 0 0 0">
                                    <site name="_tcp"/>
                                  </body>
                                </body>
                              </body>
                            </body>
                          </body>

                          <!-- ===== Realsense D435 Camera ===== -->
                          <body name="realsense_bottom_screw_frame" pos="0 0.0875 0.013" quat="0.5 -0.5 -0.5 -0.5">
                            <body name="realsense_link" pos="0.0106 0.0175 0.0125" quat="1 0 0 0">
                              <inertial mass="0.072" diaginertia="0.003881243 0.00049894 0.003879257" pos="0 0 0" quat="1 0 0 0"/>
                              <geom class="collision" type="box" pos="0 -0.0175 0" size="0.012525 0.045 0.0125"/>
                              <geom class="visual" type="mesh" mesh="MESH_d435_6743a526_0"  rgba="0.749 0.749 0.749 1" pos="0.0043 -0.0175 0" quat="0.5 0.5 0.5 0.5"/>
                              <geom class="visual" type="mesh" mesh="MESH_d435_6743a526_1"  rgba="0.749 0.749 0.749 1" pos="0.0043 -0.0175 0" quat="0.5 0.5 0.5 0.5"/>
                              <geom class="visual" type="mesh" mesh="MESH_d435_6743a526_2"  rgba="0.749 0.749 0.749 1" pos="0.0043 -0.0175 0" quat="0.5 0.5 0.5 0.5"/>
                              <geom class="visual" type="mesh" mesh="MESH_d435_6743a526_3"  rgba="0.749 0.749 0.749 1" pos="0.0043 -0.0175 0" quat="0.5 0.5 0.5 0.5"/>
                              <geom class="visual" type="mesh" mesh="MESH_d435_6743a526_4"  rgba="0.749 0.749 0.749 1" pos="0.0043 -0.0175 0" quat="0.5 0.5 0.5 0.5"/>
                              <geom class="visual" type="mesh" mesh="MESH_d435_6743a526_5"  rgba="0.749 0.749 0.749 1" pos="0.0043 -0.0175 0" quat="0.5 0.5 0.5 0.5"/>
                              <geom class="visual" type="mesh" mesh="MESH_d435_6743a526_6"  rgba="0.749 0.749 0.749 1" pos="0.0043 -0.0175 0" quat="0.5 0.5 0.5 0.5"/>
                              <geom class="visual" type="mesh" mesh="MESH_d435_6743a526_7"  rgba="0.749 0.749 0.749 1" pos="0.0043 -0.0175 0" quat="0.5 0.5 0.5 0.5"/>
                              <geom class="visual" type="mesh" mesh="MESH_d435_6743a526_8"  rgba="0.749 0.749 0.749 1" pos="0.0043 -0.0175 0" quat="0.5 0.5 0.5 0.5"/>
                              <geom class="visual" type="mesh" mesh="MESH_d435_6743a526_9"  rgba="0.749 0.749 0.749 1" pos="0.0043 -0.0175 0" quat="0.5 0.5 0.5 0.5"/>
                              <geom class="visual" type="mesh" mesh="MESH_d435_6743a526_10" rgba="0.749 0.749 0.749 1" pos="0.0043 -0.0175 0" quat="0.5 0.5 0.5 0.5"/>
                              <geom class="visual" type="mesh" mesh="MESH_d435_6743a526_11" rgba="0.749 0.749 0.749 1" pos="0.0043 -0.0175 0" quat="0.5 0.5 0.5 0.5"/>
                              <geom class="visual" type="mesh" mesh="MESH_d435_6743a526_12" rgba="0.749 0.749 0.749 1" pos="0.0043 -0.0175 0" quat="0.5 0.5 0.5 0.5"/>
                              <geom class="visual" type="mesh" mesh="MESH_d435_6743a526_13" rgba="0.749 0.749 0.749 1" pos="0.0043 -0.0175 0" quat="0.5 0.5 0.5 0.5"/>
                              <geom class="visual" type="mesh" mesh="MESH_d435_6743a526_14" rgba="0.749 0.749 0.749 1" pos="0.0043 -0.0175 0" quat="0.5 0.5 0.5 0.5"/>
                              <geom class="visual" type="mesh" mesh="MESH_d435_6743a526_15" rgba="0.749 0.749 0.749 1" pos="0.0043 -0.0175 0" quat="0.5 0.5 0.5 0.5"/>
                              <geom class="visual" type="mesh" mesh="MESH_d435_6743a526_16" rgba="0.749 0.749 0.749 1" pos="0.0043 -0.0175 0" quat="0.5 0.5 0.5 0.5"/>
                              <geom class="visual" type="mesh" mesh="MESH_d435_6743a526_17" rgba="0.749 0.749 0.749 1" pos="0.0043 -0.0175 0" quat="0.5 0.5 0.5 0.5"/>

                              <!-- 手眼 RGBD 相机 -->
                              <camera name="realsense_link_CAMERA" mode="fixed" pos="0 0 0" euler="0 -1.5708 -1.5708" fovy="75" resolution="128 128"/>
                            </body>
                          </body>
                        </body>
                      </body>
                    </body>
                  </body>
                </body>
              </body>
            </body>
          </body>
        </body>
      </body>
      <body name="ur_base" pos="0 0 0" quat="6.123233995736766e-17 0 0 1"/>
    </body>
  </worldbody>

</mujoco>
